Workbook

Sheet Amazon
A1: Bond Ticker | B1: CUSIP | C1: Company Name | D1: Settlement Date | E1: Years to Maturity | F1: FV | G1: Coupon Pmt | H1: N | I1: I/Y | J1: PV | K1: t | L1: First Coupon Date | M1: Recent Coupon Payment | N1: Coupon Months | P1: Coupon payment dates
A2: Amazon.com 3.6% 04/32 | B2: 023135CH7 | C2: AMAZON.COM, INC | D2: 45767 | E2: =_xlfn.DAYS(H5,D2)/365 -> 6.9863014 | F2: 100 | G2: =F2*L5/2 -> 1.8 | H2: =E2*2 -> 13.972603 | I2: =RATE(H2,G2,J2,F2,0) -> 0.023168803 | J2: -93.89 | K2: =_xlfn.DAYS(D2,P2) -> 7 | L2: 44847 | M2: 45760 | N2: April | O2: Oct | P2: 45760 | Q2: 45943
A4: Bond Ticker | B4: CUSIP | C4: Company Name | D4: Rating | E4: Amount Issued $M | F4: Amount Outstanding $M | G4: Issue Date | H4: Date of Maturity | I4: Embeded Option | J4: Call Date | K4: Call Price | L4: Coupon | M4: Coupon Freq | N4: Annual YTM | O4: Annual Yield to call
A5: Amazon.com 3.6% 04/32 | B5: 023135CH7 | C5: AMAZON.COM, INC | D5: AA- | E5: 2500 | F5: 2500 | G5: 44664 | H5: 48317 | I5: Y | J5: 48226 | K5: 100 | L5: 0.036 | M5: SA | N5: =B16 -> 0.046337606 | O5: =B30 -> 0.046814689
A8: Parameters | B8: Values | E8: Period | F8: Cash Flow (CF) | G8: Discount Factors (DF) | H8: Present Value (PV) | I8: Time * PV | J8: Convexity
A9: Flat Price | B9: =J2 -> -93.89 | E9: 1 | F9: =$G$2 -> 1.8 | G9: =(1+$B$17)^-E9 -> 0.97735584 | H9: =F9*G9 -> 1.7592405 | I9: =E9*H9 -> 1.7592405 | J9: =E9*(E9+1)*H9 -> 3.518481
A10: Days since last payment | B10: =K2 -> 7 | E10: 2 | F10: =$G$2 -> 1.8 | G10: =(1+$B$17)^-E10 -> 0.95522443 | H10: =F10*G10 -> 1.719404 | I10: =E10*H10 -> 3.4388079 | J10: =E10*(E10+1)*H10 -> 10.316424
A11: Total days in a coupon period | B11: =DAYS360(P2,Q2,FALSE) -> 180 | E11: 3 | F11: =$G$2 -> 1.8 | G11: =(1+$B$17)^-E11 -> 0.93359417 | H11: =F11*G11 -> 1.6804695 | I11: =E11*H11 -> 5.0414085 | J11: =E11*(E11+1)*H11 -> 20.165634
A12: Annual coupon rate | B12: =L5 -> 0.036 | E12: 4 | F12: =$G$2 -> 1.8 | G12: =(1+$B$17)^-E12 -> 0.91245371 | H12: =F12*G12 -> 1.6424167 | I12: =E12*H12 -> 6.5696667 | J12: =E12*(E12+1)*H12 -> 32.848334
A13: Semi annual coupon payment | B13: =G2 -> 1.8 | E13: 5 | F13: =$G$2 -> 1.8 | G13: =(1+$B$17)^-E13 -> 0.89179196 | H13: =F13*G13 -> 1.6052255 | I13: =E13*H13 -> 8.0261276 | J13: =E13*(E13+1)*H13 -> 48.156766
A14: Accrued Interest | B14: =(B10/B11)*B13 -> 0.07 | E14: 6 | F14: =$G$2 -> 1.8 | G14: =(1+$B$17)^-E14 -> 0.87159807 | H14: =F14*G14 -> 1.5688765 | I14: =E14*H14 -> 9.4132592 | J14: =E14*(E14+1)*H14 -> 65.892814
A15: Full Price | B15: =B14-B9 -> 93.96 | C15: Flat price + accrued interest | E15: 7 | F15: =$G$2 -> 1.8 | G15: =(1+$B$17)^-E15 -> 0.85186146 | H15: =F15*G15 -> 1.5333506 | I15: =E15*H15 -> 10.733454 | J15: =E15*(E15+1)*H15 -> 85.867635
A16: YTM | B16: =RATE(H2,G2,J2,F2)*2 -> 0.046337606 | E16: 8 | F16: =$G$2 -> 1.8 | G16: =(1+$B$17)^-E16 -> 0.83257177 | H16: =F16*G16 -> 1.4986292 | I16: =E16*H16 -> 11.989033 | J16: =E16*(E16+1)*H16 -> 107.9013
A17: Discount Factor (semi annual yield) | B17: =B16/2 -> 0.023168803 | E17: 9 | F17: =$G$2 -> 1.8 | G17: =(1+$B$17)^-E17 -> 0.81371888 | H17: =F17*G17 -> 1.464694 | I17: =E17*H17 -> 13.182246 | J17: =E17*(E17+1)*H17 -> 131.82246
A18: Macaulay Duration | B18: =I23/H23 -> 12.439986 | E18: 10 | F18: =$G$2 -> 1.8 | G18: =(1+$B$17)^-E18 -> 0.79529289 | H18: =F18*G18 -> 1.4315272 | I18: =E18*H18 -> 14.315272 | J18: =E18*(E18+1)*H18 -> 157.46799
A19: Modified duration | B19: =B18/(1+B17) -> 12.158293 | E19: 11 | F19: =$G$2 -> 1.8 | G19: =(1+$B$17)^-E19 -> 0.77728415 | H19: =F19*G19 -> 1.3991115 | I19: =E19*H19 -> 15.390226 | J19: =E19*(E19+1)*H19 -> 184.68271
A20: Convexity | B20: =J23/(B15*(1+B17)^2) -> 170.98198 | C20: convexity/(full price*(1+semi annual yield)^2) | E20: 12 | F20: =$G$2 -> 1.8 | G20: =(1+$B$17)^-E20 -> 0.7596832 | H20: =F20*G20 -> 1.3674298 | I20: =E20*H20 -> 16.409157 | J20: =E20*(E20+1)*H20 -> 213.31904
A21: Yield shift (bps) | B21: 100 | E21: 13 | F21: =$G$2 -> 1.8 | G21: =(1+$B$17)^-E21 -> 0.74248081 | H21: =F21*G21 -> 1.3364655 | I21: =E21*H21 -> 17.374051 | J21: =E21*(E21+1)*H21 -> 243.23671
A22: Yield change in decimal | B22: =B21/10000 -> 0.01 | E22: 14 | F22: =$G$2+$F$2 -> 101.8 | G22: =(1+$B$17)^-E22 -> 0.72566795 | H22: =F22*G22 -> 73.872997 | I22: =E22*H22 -> 1034.222 | J22: =E22*(E22+1)*H22 -> 15513.329
A23: Yield change positive (+100 bps) | B23: =B16+B22 -> 0.056337606 | E23: Total | F23: =SUM(F9:F22) -> 125.2 | G23: =SUM(G9:G22) -> 11.840579 | H23: =SUM(H9:H22) -> 93.879838 | I23: =SUM(I9:I22) -> 1167.8639 | J23: =SUM(J9:J22) -> 16818.526
A24: Yield change negative (-100 bps) | B24: =B16-B22 -> 0.036337606
A25: semi annual yield change with +100 bps | B25: =B23/2 -> 0.028168803
A26: semi annual yield change with -100 bps | B26: =B24/2 -> 0.018168803
A27: New Price with +100 bps | B27: =H45 -> 88.368538
A28: New Price with -100 bps | B28: =O45 -> 99.792984
A29: Number of periods (Yield to Call) | B29: =DAYS360(D2,J5,0)/365*2 -> 13.276712 | E29: Bond Price with +100 bps yield | L29: Bond Price with -100 bps yield
A30: YTC (Yield to call) | B30: =RATE(B29,G2,J2,K5)*2 -> 0.046814689 | E30: Period | F30: Payment SA | G30: Discount factor | H30: Present value | L30: Period | M30: Payment SA | N30: Discount factor | O30: Present value
E31: 1 | F31: =$G$2 -> 1.8 | G31: =1/(1+$B$25)^E31 -> 0.97260294 | H31: =F31*G31 -> 1.7506853 | L31: 1 | M31: =$G$2 -> 1.8 | N31: =1/(1+$B$26)^L31 -> 0.98215541 | O31: =M31*N31 -> 1.7678797
E32: 2 | F32: =$G$2 -> 1.8 | G32: =1/(1+$B$25)^E32 -> 0.94595648 | H32: =F32*G32 -> 1.7027217 | L32: 2 | M32: =$G$2 -> 1.8 | N32: =1/(1+$B$26)^L32 -> 0.96462925 | O32: =M32*N32 -> 1.7363327
E33: 3 | F33: =$G$2 -> 1.8 | G33: =1/(1+$B$25)^E33 -> 0.92004005 | H33: =F33*G33 -> 1.6560721 | L33: 3 | M33: =$G$2 -> 1.8 | N33: =1/(1+$B$26)^L33 -> 0.94741584 | O33: =M33*N33 -> 1.7053485
E34: 4 | F34: =$G$2 -> 1.8 | G34: =1/(1+$B$25)^E34 -> 0.89483366 | H34: =F34*G34 -> 1.6107006 | L34: 4 | M34: =$G$2 -> 1.8 | N34: =1/(1+$B$26)^L34 -> 0.9305096 | O34: =M34*N34 -> 1.6749173
E35: 5 | F35: =$G$2 -> 1.8 | G35: =1/(1+$B$25)^E35 -> 0.87031785 | H35: =F35*G35 -> 1.5665721 | L35: 5 | M35: =$G$2 -> 1.8 | N35: =1/(1+$B$26)^L35 -> 0.91390503 | O35: =M35*N35 -> 1.6450291
E36: 6 | F36: =$G$2 -> 1.8 | G36: =1/(1+$B$25)^E36 -> 0.84647369 | H36: =F36*G36 -> 1.5236527 | L36: 6 | M36: =$G$2 -> 1.8 | N36: =1/(1+$B$26)^L36 -> 0.89759678 | O36: =M36*N36 -> 1.6156742
E37: 7 | F37: =$G$2 -> 1.8 | G37: =1/(1+$B$25)^E37 -> 0.8232828 | H37: =F37*G37 -> 1.481909 | L37: 7 | M37: =$G$2 -> 1.8 | N37: =1/(1+$B$26)^L37 -> 0.88157953 | O37: =M37*N37 -> 1.5868432
E38: 8 | F38: =$G$2 -> 1.8 | G38: =1/(1+$B$25)^E38 -> 0.80072727 | H38: =F38*G38 -> 1.4413091 | L38: 8 | M38: =$G$2 -> 1.8 | N38: =1/(1+$B$26)^L38 -> 0.86584811 | O38: =M38*N38 -> 1.5585266
E39: 9 | F39: =$G$2 -> 1.8 | G39: =1/(1+$B$25)^E39 -> 0.7787897 | H39: =F39*G39 -> 1.4018215 | L39: 9 | M39: =$G$2 -> 1.8 | N39: =1/(1+$B$26)^L39 -> 0.8503974 | O39: =M39*N39 -> 1.5307153
E40: 10 | F40: =$G$2 -> 1.8 | G40: =1/(1+$B$25)^E40 -> 0.75745315 | H40: =F40*G40 -> 1.3634157 | L40: 10 | M40: =$G$2 -> 1.8 | N40: =1/(1+$B$26)^L40 -> 0.83522241 | O40: =M40*N40 -> 1.5034003
E41: 11 | F41: =$G$2 -> 1.8 | G41: =1/(1+$B$25)^E41 -> 0.73670116 | H41: =F41*G41 -> 1.3260621 | L41: 11 | M41: =$G$2 -> 1.8 | N41: =1/(1+$B$26)^L41 -> 0.82031821 | O41: =M41*N41 -> 1.4765728
E42: 12 | F42: =$G$2 -> 1.8 | G42: =1/(1+$B$25)^E42 -> 0.71651772 | H42: =F42*G42 -> 1.2897319 | L42: 12 | M42: =$G$2 -> 1.8 | N42: =1/(1+$B$26)^L42 -> 0.80567997 | O42: =M42*N42 -> 1.4502239
E43: 13 | F43: =$G$2 -> 1.8 | G43: =1/(1+$B$25)^E43 -> 0.69688724 | H43: =F43*G43 -> 1.254397 | L43: 13 | M43: =$G$2 -> 1.8 | N43: =1/(1+$B$26)^L43 -> 0.79130294 | O43: =M43*N43 -> 1.4243453
...

Sheet Microsoft
A1: Bond Ticker | B1: CUSIP | C1: Company Name | D1: Settlement Date | E1: Years to Maturity | F1: FV | G1: Coupon Pmt | H1: N | I1: I/Y | J1: PV | K1: t | L1: First Coupon Date | M1: Recent Coupon Payment | N1: Coupon Months | P1: Coupon Dates
A2: Microsoft 3.5% 02/35 | B2: 594918BC7 | C2: MICROSOFT CORP | D2: 45767 | E2: 10 | F2: 100 | G2: =F2*L5/2 -> 1.75 | H2: =E2*2 -> 20 | I2: =N5/2 -> 0.02261732 | J2: -91.84 | K2: =DAYS360(M2,D2,0) -> 68 | L2: 42228 | M2: 45700 | N2: Feb | O2: Aug | P2: 45700 | Q2: 45881
A4: Bond Ticker | B4: CUSIP | C4: Company Name | D4: Rating | E4: Amount Issued $M | F4: Amount Outstanding $M | G4: Issue Date | H4: Date of Maturity | I4: Embeded Option | J4: Call Date | K4: Call Price | L4: Coupon | M4: Coupon Freq | N4: Annual YTM | O4: Annual YTC
A5: =A2 -> Microsoft 3.5% 02/35 | B5: =B2 -> 594918BC7 | C5: =C2 -> MICROSOFT CORP | D5: Aaa | E5: 1500 | F5: 1500 | G5: 42047 | H5: 49352 | I5: Call | J5: 49168 | K5: 100 | L5: 0.035 | M5: SA | N5: =B16 -> 0.045234641 | O5: =B30 -> 0.045866492
A8: Parameters | B8: Values | D8: Period | E8: Cash Flow (CF) | F8: Discount Factors (DF) | G8: Present Value (PV) | H8: Time * PV | I8: Convexity
A9: Flat Price | B9: =J2 -> -91.84 | D9: 1 | E9: =$G$2 -> 1.75 | F9: =(1+$B$17)^-D9 -> 0.97788291 | G9: =E9*F9 -> 1.7112951 | H9: =D9*G9 -> 1.7112951 | I9: =D9*(D9+1)*G9 -> 3.4225902
A10: Days since last payment | B10: =K2 -> 68 | D10: 2 | E10: =$G$2 -> 1.75 | F10: =(1+$B$17)^-D10 -> 0.95625498 | G10: =E10*F10 -> 1.6734462 | H10: =D10*G10 -> 3.3468924 | I10: =D10*(D10+1)*G10 -> 10.040677
A11: Total days in a coupon period | B11: =DAYS360(P2,Q2,0) -> 180 | D11: 3 | E11: =$G$2 -> 1.75 | F11: =(1+$B$17)^-D11 -> 0.9351054 | G11: =E11*F11 -> 1.6364345 | H11: =D11*G11 -> 4.9093034 | I11: =D11*(D11+1)*G11 -> 19.637214
A12: Annual coupon rate | B12: =L5 -> 0.035 | D12: 4 | E12: =$G$2 -> 1.75 | F12: =(1+$B$17)^-D12 -> 0.91442359 | G12: =E12*F12 -> 1.6002413 | H12: =D12*G12 -> 6.4009652 | I12: =D12*(D12+1)*G12 -> 32.004826
A13: Semi annual coupon payment | B13: =G2 -> 1.75 | D13: 5 | E13: =$G$2 -> 1.75 | F13: =(1+$B$17)^-D13 -> 0.8941992 | G13: =E13*F13 -> 1.5648486 | H13: =D13*G13 -> 7.824243 | I13: =D13*(D13+1)*G13 -> 46.945458
A14: Accrued Interest | B14: =(B10/B11)*B13 -> 0.66111111 | D14: 6 | E14: =$G$2 -> 1.75 | F14: =(1+$B$17)^-D14 -> 0.87442212 | G14: =E14*F14 -> 1.5302387 | H14: =D14*G14 -> 9.1814322 | I14: =D14*(D14+1)*G14 -> 64.270026
A15: Full Price | B15: =B14-B9 -> 92.501111 | D15: 7 | E15: =$G$2 -> 1.75 | F15: =(1+$B$17)^-D15 -> 0.85508244 | G15: =E15*F15 -> 1.4963943 | H15: =D15*G15 -> 10.47476 | I15: =D15*(D15+1)*G15 -> 83.79808
A16: YTM | B16: =RATE(H2,G2,J2,F2,0)*2 -> 0.045234641 | D16: 8 | E16: =$G$2 -> 1.75 | F16: =(1+$B$17)^-D16 -> 0.83617051 | G16: =E16*F16 -> 1.4632984 | H16: =D16*G16 -> 11.706387 | I16: =D16*(D16+1)*G16 -> 105.35748
A17: Discount Factor (semi annual yield) | B17: =B16/2 -> 0.02261732 | D17: 9 | E17: =$G$2 -> 1.75 | F17: =(1+$B$17)^-D17 -> 0.81767685 | G17: =E17*F17 -> 1.4309345 | H17: =D17*G17 -> 12.87841 | I17: =D17*(D17+1)*G17 -> 128.7841
A18: Macaulay Duration | B18: =H29/G29 -> 16.888259 | D18: 10 | E18: =$G$2 -> 1.75 | F18: =(1+$B$17)^-D18 -> 0.79959222 | G18: =E18*F18 -> 1.3992864 | H18: =D18*G18 -> 13.992864 | I18: =D18*(D18+1)*G18 -> 153.9215
A19: Modified duration | B19: =B18/(1+B17) -> 16.51474 | D19: 11 | E19: =$G$2 -> 1.75 | F19: =(1+$B$17)^-D19 -> 0.78190756 | G19: =E19*F19 -> 1.3683382 | H19: =D19*G19 -> 15.051721 | I19: =D19*(D19+1)*G19 -> 180.62065
A20: Convexity | B20: =I29/(B15*(1+B17)^2) -> 317.38072 | D20: 12 | E20: =$G$2 -> 1.75 | F20: =(1+$B$17)^-D20 -> 0.76461404 | G20: =E20*F20 -> 1.3380746 | H20: =D20*G20 -> 16.056895 | I20: =D20*(D20+1)*G20 -> 208.73963
A21: Yield shift (bps) | B21: 100 | D21: 13 | E21: =$G$2 -> 1.75 | F21: =(1+$B$17)^-D21 -> 0.747703 | G21: =E21*F21 -> 1.3084803 | H21: =D21*G21 -> 17.010243 | I21: =D21*(D21+1)*G21 -> 238.14341
A22: Yield change in decimal | B22: =B21/10000 -> 0.01 | D22: 14 | E22: =$G$2 -> 1.75 | F22: =(1+$B$17)^-D22 -> 0.73116599 | G22: =E22*F22 -> 1.2795405 | H22: =D22*G22 -> 17.913567 | I22: =D22*(D22+1)*G22 -> 268.7035
A23: Annual yield with +100 bps change | B23: =N5+0.01 -> 0.055234641 | D23: 15 | E23: =$G$2 -> 1.75 | F23: =(1+$B$17)^-D23 -> 0.71499472 | G23: =E23*F23 -> 1.2512408 | H23: =D23*G23 -> 18.768611 | I23: =D23*(D23+1)*G23 -> 300.29778
A24: Annual yield with -100 bps change | B24: =N5-0.01 -> 0.035234641 | D24: 16 | E24: =$G$2 -> 1.75 | F24: =(1+$B$17)^-D24 -> 0.69918112 | G24: =E24*F24 -> 1.223567 | H24: =D24*G24 -> 19.577071 | I24: =D24*(D24+1)*G24 -> 332.81021
A25: Semi annual yield with +100bps change | B25: =B23/2 -> 0.02761732 | D25: 17 | E25: =$G$2 -> 1.75 | F25: =(1+$B$17)^-D25 -> 0.68371727 | G25: =E25*F25 -> 1.1965052 | H25: =D25*G25 -> 20.340589 | I25: =D25*(D25+1)*G25 -> 366.1306
A26: Semi annual yield with -100bps change | B26: =B24/2 -> 0.01761732 | D26: 18 | E26: =$G$2 -> 1.75 | F26: =(1+$B$17)^-D26 -> 0.66859543 | G26: =E26*F26 -> 1.170042 | H26: =D26*G26 -> 21.060756 | I26: =D26*(D26+1)*G26 -> 400.15436
A27: New Price with +100 bps change | B27: =G53 -> 84.610979 | D27: 19 | E27: =$G$2 -> 1.75 | F27: =(1+$B$17)^-D27 -> 0.65380804 | G27: =E27*F27 -> 1.1441641 | H27: =D27*G27 -> 21.739117 | I27: =D27*(D27+1)*G27 -> 434.78235
A28: New Price with -100 bps change | B28: =M53 -> 99.803679 | D28: 20 | E28: =$G$2+F2 -> 101.75 | F28: =(1+$B$17)^-D28 -> 0.63934771 | G28: =E28*F28 -> 65.05363 | H28: =D28*G28 -> 1301.0726 | I28: =D28*(D28+1)*G28 -> 27322.524
A29: Number of periods (Yield to Call) | B29: =DAYS360(D2,J5,0)/360*2 -> 18.622222 | D29: Total | E29: =SUM(E9:E28) -> 135 | F29: =SUM(F9:F28) -> 15.945845 | G29: =SUM(G9:G28) -> 91.84 | H29: =SUM(H9:H28) -> 1551.0177 | I29: =SUM(I9:I28) -> 30701.089
A30: YTC (Yield to call) | B30: =RATE(B29,G2,J2,K5)*2 -> 0.045866492
D31: Bond Price with +100 bps yield | J31: Bond Price with -100 bps yield
D32: Period | E32: Payment SA | F32: Discount factor | G32: Present value | J32: Period | K32: Payment SA | L32: Discount Factor | M32: Present Value
D33: 1 | E33: =$G$2 -> 1.75 | F33: =1/(1+$B$25)^D33 -> 0.9731249 | G33: =E33*F33 -> 1.7029686 | J33: 1 | K33: =$G$2 -> 1.75 | L33: =1/(1+$B$26)^J33 -> 0.98268768 | M33: =K33*L33 -> 1.7197034
D34: 2 | E34: =$G$2 -> 1.75 | F34: =1/(1+$B$25)^D34 -> 0.94697207 | G34: =E34*F34 -> 1.6572011 | J34: 2 | K34: =$G$2 -> 1.75 | L34: =1/(1+$B$26)^J34 -> 0.96567507 | M34: =K34*L34 -> 1.6899314
D35: 3 | E35: =$G$2 -> 1.75 | F35: =1/(1+$B$25)^D35 -> 0.9215221 | G35: =E35*F35 -> 1.6126637 | J35: 3 | K35: =$G$2 -> 1.75 | L35: =1/(1+$B$26)^J35 -> 0.94895699 | M35: =K35*L35 -> 1.6606747
D36: 4 | E36: =$G$2 -> 1.75 | F36: =1/(1+$B$25)^D36 -> 0.8967561 | G36: =E36*F36 -> 1.5693232 | J36: 4 | K36: =$G$2 -> 1.75 | L36: =1/(1+$B$26)^J36 -> 0.93252834 | M36: =K36*L36 -> 1.6319246
D37: 5 | E37: =$G$2 -> 1.75 | F37: =1/(1+$B$25)^D37 -> 0.87265568 | G37: =E37*F37 -> 1.5271474 | J37: 5 | K37: =$G$2 -> 1.75 | L37: =1/(1+$B$26)^J37 -> 0.91638411 | M37: =K37*L37 -> 1.6036722
D38: 6 | E38: =$G$2 -> 1.75 | F38: =1/(1+$B$25)^D38 -> 0.84920297 | G38: =E38*F38 -> 1.4861052 | J38: 6 | K38: =$G$2 -> 1.75 | L38: =1/(1+$B$26)^J38 -> 0.90051937 | M38: =K38*L38 -> 1.5759089
D39: 7 | E39: =$G$2 -> 1.75 | F39: =1/(1+$B$25)^D39 -> 0.82638056 | G39: =E39*F39 -> 1.446166 | J39: 7 | K39: =$G$2 -> 1.75 | L39: =1/(1+$B$26)^J39 -> 0.88492929 | M39: =K39*L39 -> 1.5486262
D40: 8 | E40: =$G$2 -> 1.75 | F40: =1/(1+$B$25)^D40 -> 0.80417149 | G40: =E40*F40 -> 1.4073001 | J40: 8 | K40: =$G$2 -> 1.75 | L40: =1/(1+$B$26)^J40 -> 0.8696091 | M40: =K40*L40 -> 1.5218159
D41: 9 | E41: =$G$2 -> 1.75 | F41: =1/(1+$B$25)^D41 -> 0.7825593 | G41: =E41*F41 -> 1.3694788 | J41: 9 | K41: =$G$2 -> 1.75 | L41: =1/(1+$B$26)^J41 -> 0.85455415 | M41: =K41*L41 -> 1.4954698
D42: 10 | E42: =$G$2 -> 1.75 | F42: =1/(1+$B$25)^D42 -> 0.76152794 | G42: =E42*F42 -> 1.3326739 | J42: 10 | K42: =$G$2 -> 1.75 | L42: =1/(1+$B$26)^J42 -> 0.83975983 | M42: =K42*L42 -> 1.4695797
D43: 11 | E43: =$G$2 -> 1.75 | F43: =1/(1+$B$25)^D43 -> 0.7410618 | G43: =E43*F43 -> 1.2968582 | J43: 11 | K43: =$G$2 -> 1.75 | L43: =1/(1+$B$26)^J43 -> 0.82522164 | M43: =K43*L43 -> 1.4441379
...

Sheet Disney
A1: Bond Ticker | B1: CUSIP | C1: Company Name | D1: Settlement Date | E1: Years to Maturity | F1: FV | G1: Coupon Pmt | H1: N | I1: I/Y | J1: PV | K1: t | L1: First Coupon Date | M1: Recent Coupon Payment | N1: Coupon Months | P1: Maturity date
A2: DIS 6.2 12/15/34 | B2: US254687DZ66 | C2: Walt Disney | D2: 45767 | E2: 9.5 | F2: 100 | G2: =(100*6.2%)/2 -> 3.1 | H2: =E2*2 -> 19 | I2: =RATE($H$2,$G$2,-$J$2,$F$2,0) -> 0.025315835 | J2: 108.49 | K2: 123 | L2: 23/01/20 | M2: 45641 | N2: June | O2: December | P2: 49293
A4: Bond | B4: t | C4: T | D4: t/T | E4: Accured Interest | F4: Flat Price | G4: Full Price
A5: DIS 6.2 12/15/34 | B5: =_xlfn.DAYS(D2,M2) -> 126 | C5: 180 | D5: =B5/C5 -> 0.7 | E5: =D5*G2 -> 2.17 | F5: =J2 -> 108.49 | G5: =F5+E5 -> 110.66
A7: Bond Ticker | B7: CUSIP | C7: Company Name | D7: Rating | E7: Amount Issued $M | F7: Amount Outstanding $M | G7: Issue Date | H7: Date of Maturity | I7: Coupon | J7: Coupon Freq | K7: Annual YTM
A8: DIS 6.2 12/15/34 | B8: US254687DZ66 | C8: Walt Disney | D8: AA | E8: 984.22 | F8: 1.75 | H8: 49293 | I8: 0.062 | J8: Semi-Annual | K8: =RATE($H$2,$G$2,-$J$2,$F$2,0)*2 -> 0.050631671
A11: Parameters | B11: Values
A12: Flat Price | B12: =F5 -> 108.49 | F12: Period | G12: Cash Flow (CF) | H12: Discount Factors (DF) | I12: Present Value (PV) | J12: Time * PV | K12: Convexity
A13: Days since last payment | B13: =B5 -> 126 | F13: 1 | G13: =$G$2 -> 3.1 | H13: =(1+$B$20)^-F13 -> 0.97530923 | I13: =G13*H13 -> 3.0234586 | J13: =F13*I13 -> 3.0234586 | K13: =F13*(F13+1)*I13 -> 6.0469172
A14: Total days in a coupon period | B14: =C5 -> 180 | F14: 2 | G14: =$G$2 -> 3.1 | H14: =(1+$B$20)^-F14 -> 0.9512281 | I14: =G14*H14 -> 2.9488071 | J14: =F14*I14 -> 5.8976142 | K14: =F14*(F14+1)*I14 -> 17.692843
A15: Annual coupon rate | B15: =I8 -> 0.062 | F15: 3 | G15: =$G$2 -> 3.1 | H15: =(1+$B$20)^-F15 -> 0.92774155 | I15: =G15*H15 -> 2.8759988 | J15: =F15*I15 -> 8.6279964 | K15: =F15*(F15+1)*I15 -> 34.511986
A16: Semi annual coupon payment | B16: =G2 -> 3.1 | F16: 4 | G16: =$G$2 -> 3.1 | H16: =(1+$B$20)^-F16 -> 0.90483489 | I16: =G16*H16 -> 2.8049882 | J16: =F16*I16 -> 11.219953 | K16: =F16*(F16+1)*I16 -> 56.099763
A17: Accrued Interest | B17: =(B13/B14)*B16 -> 2.17 | F17: 5 | G17: =$G$2 -> 3.1 | H17: =(1+$B$20)^-F17 -> 0.88249383 | I17: =G17*H17 -> 2.7357309 | J17: =F17*I17 -> 13.678654 | K17: =F17*(F17+1)*I17 -> 82.071926
A18: Full Price | B18: =G5 -> 110.66 | C18: Flat price + accrued interest | F18: 6 | G18: =$G$2 -> 3.1 | H18: =(1+$B$20)^-F18 -> 0.86070438 | I18: =G18*H18 -> 2.6681836 | J18: =F18*I18 -> 16.009101 | K18: =F18*(F18+1)*I18 -> 112.06371
A19: YTM | B19: =I2*2 -> 0.050631671 | F19: 7 | G19: =$G$2 -> 3.1 | H19: =(1+$B$20)^-F19 -> 0.83945292 | I19: =G19*H19 -> 2.6023041 | J19: =F19*I19 -> 18.216128 | K19: =F19*(F19+1)*I19 -> 145.72903
A20: Discount Factor (semi annual yield) | B20: =B19/2 -> 0.025315835 | F20: 8 | G20: =$G$2 -> 3.1 | H20: =(1+$B$20)^-F20 -> 0.81872619 | I20: =G20*H20 -> 2.5380512 | J20: =F20*I20 -> 20.304409 | K20: =F20*(F20+1)*I20 -> 182.73968
A21: Macaulay Duration | B21: =J32/I32 -> 14.840001 | F21: 9 | G21: =$G$2 -> 3.1 | H21: =(1+$B$20)^-F21 -> 0.79851121 | I21: =G21*H21 -> 2.4753847 | J21: =F21*I21 -> 22.278463 | K21: =F21*(F21+1)*I21 -> 222.78463
A22: Modified duration | B22: =B21/(1+B20) -> 14.47359 | F22: 10 | G22: =$G$2 -> 3.1 | H22: =(1+$B$20)^-F22 -> 0.77879535 | I22: =G22*H22 -> 2.4142656 | J22: =F22*I22 -> 24.142656 | K22: =F22*(F22+1)*I22 -> 265.56922
A23: Convexity | B23: =K32/(B18*(1+B20)^2) -> 252.69843 | C23: convexity/(full price*(1+semi annual yield)^2) | F23: 11 | G23: =$G$2 -> 3.1 | H23: =(1+$B$20)^-F23 -> 0.7595663 | I23: =G23*H23 -> 2.3546555 | J23: =F23*I23 -> 25.901211 | K23: =F23*(F23+1)*I23 -> 310.81453
A24: Yield shift (bps) | B24: 100 | F24: 12 | G24: =$G$2 -> 3.1 | H24: =(1+$B$20)^-F24 -> 0.74081202 | I24: =G24*H24 -> 2.2965173 | J24: =F24*I24 -> 27.558207 | K24: =F24*(F24+1)*I24 -> 358.25669
A25: Yield change in decimal | B25: =B24/10000 -> 0.01 | F25: 13 | G25: =$G$2 -> 3.1 | H25: =(1+$B$20)^-F25 -> 0.72252081 | I25: =G25*H25 -> 2.2398145 | J25: =F25*I25 -> 29.117588 | K25: =F25*(F25+1)*I25 -> 407.64624
A26: Yield change positive (+100 bps) | B26: =B19+B25 -> 0.060631671 | F26: 14 | G26: =$G$2 -> 3.1 | H26: =(1+$B$20)^-F26 -> 0.70468121 | I26: =G26*H26 -> 2.1845118 | J26: =F26*I26 -> 30.583165 | K26: =F26*(F26+1)*I26 -> 458.74747
A27: Yield change negative (-100 bps) | B27: =B19-B25 -> 0.040631671 | F27: 15 | G27: =$G$2 -> 3.1 | H27: =(1+$B$20)^-F27 -> 0.68728209 | I27: =G27*H27 -> 2.1305745 | J27: =F27*I27 -> 31.958617 | K27: =F27*(F27+1)*I27 -> 511.33788
A28: semi annual yield change with +100 bps | B28: =B26/2 -> 0.030315835 | F28: 16 | G28: =$G$2 -> 3.1 | H28: =(1+$B$20)^-F28 -> 0.67031257 | I28: =G28*H28 -> 2.077969 | J28: =F28*I28 -> 33.247503 | K28: =F28*(F28+1)*I28 -> 565.20756
A29: semi annual yield change with -100 bps | B29: =B27/2 -> 0.020315835 | F29: 17 | G29: =$G$2 -> 3.1 | H29: =(1+$B$20)^-F29 -> 0.65376204 | I29: =G29*H29 -> 2.0266623 | J29: =F29*I29 -> 34.453259 | K29: =F29*(F29+1)*I29 -> 620.15867
A30: New Price with +100 bps | B30: =I56 -> 100.97725 | F30: 18 | G30: =$G$2 -> 3.1 | H30: =(1+$B$20)^-F30 -> 0.63762015 | I30: =G30*H30 -> 1.9766225 | J30: =F30*I30 -> 35.579204 | K30: =F30*(F30+1)*I30 -> 676.00488
A31: New Price with -100 bps | B31: =O56 -> 116.70243 | F31: 19 | G31: =$G$2+F2 -> 103.1 | H31: =(1+$B$20)^-F31 -> 0.62187682 | I31: =G31*H31 -> 64.1155 | J31: =F31*I31 -> 1218.1945 | K31: =F31*(F31+1)*I31 -> 24363.89
F32: Total | G32: =SUM(G13:G31) -> 158.9 | H32: =SUM(H13:H31) -> 14.936232 | I32: =SUM(I13:I31) -> 108.49 | J32: =SUM(J13:J31) -> 1609.9917 | K32: =SUM(K13:K31) -> 29397.374
F36: Period | G36: Payment SA | H36: Discount factor | I36: Present value | L36: Period | M36: Payment SA | N36: Discount factor | O36: Present value
F37: 1 | G37: =$G$2 -> 3.1 | H37: =(1+$B$28)^-F37 -> 0.97057617 | I37: =G37*H37 -> 3.0087861 | L37: 1 | M37: =$G$2 -> 3.1 | N37: =(1+$B$29)^-L37 -> 0.98008868 | O37: =M37*N37 -> 3.0382749
F38: 2 | G38: =$G$2 -> 3.1 | H38: =(1+$B$28)^-F38 -> 0.94201811 | I38: =G38*H38 -> 2.9202561 | L38: 2 | M38: =$G$2 -> 3.1 | N38: =(1+$B$29)^-L38 -> 0.96057382 | O38: =M38*N38 -> 2.9777788
F39: 3 | G39: =$G$2 -> 3.1 | H39: =(1+$B$28)^-F39 -> 0.91430033 | I39: =G39*H39 -> 2.834331 | L39: 3 | M39: =$G$2 -> 3.1 | N39: =(1+$B$29)^-L39 -> 0.94144753 | O39: =M39*N39 -> 2.9184873
F40: 4 | G40: =$G$2 -> 3.1 | H40: =(1+$B$28)^-F40 -> 0.88739811 | I40: =G40*H40 -> 2.7509342 | L40: 4 | M40: =$G$2 -> 3.1 | N40: =(1+$B$29)^-L40 -> 0.92270206 | O40: =M40*N40 -> 2.8603764
F41: 5 | G41: =$G$2 -> 3.1 | H41: =(1+$B$28)^-F41 -> 0.86128746 | I41: =G41*H41 -> 2.6699911 | L41: 5 | M41: =$G$2 -> 3.1 | N41: =(1+$B$29)^-L41 -> 0.90432985 | O41: =M41*N41 -> 2.8034225
F42: 6 | G42: =$G$2 -> 3.1 | H42: =(1+$B$28)^-F42 -> 0.83594509 | I42: =G42*H42 -> 2.5914298 | L42: 6 | M42: =$G$2 -> 3.1 | N42: =(1+$B$29)^-L42 -> 0.88632345 | O42: =M42*N42 -> 2.7476027
F43: 7 | G43: =$G$2 -> 3.1 | H43: =(1+$B$28)^-F43 -> 0.81134839 | I43: =G43*H43 -> 2.51518 | L43: 7 | M43: =$G$2 -> 3.1 | N43: =(1+$B$29)^-L43 -> 0.86867558 | O43: =M43*N43 -> 2.6928943
F44: 8 | G44: =$G$2 -> 3.1 | H44: =(1+$B$28)^-F44 -> 0.78747541 | I44: =G44*H44 -> 2.4411738 | L44: 8 | M44: =$G$2 -> 3.1 | N44: =(1+$B$29)^-L44 -> 0.8513791 | O44: =M44*N44 -> 2.6392752
F45: 9 | G45: =$G$2 -> 3.1 | H45: =(1+$B$28)^-F45 -> 0.76430487 | I45: =G45*H45 -> 2.3693451 | L45: 9 | M45: =$G$2 -> 3.1 | N45: =(1+$B$29)^-L45 -> 0.83442702 | O45: =M45*N45 -> 2.5867238
F46: 10 | G46: =$G$2 -> 3.1 | H46: =(1+$B$28)^-F46 -> 0.7418161 | I46: =G46*H46 -> 2.2996299 | L46: 10 | M46: =$G$2 -> 3.1 | N46: =(1+$B$29)^-L46 -> 0.81781247 | O46: =M46*N46 -> 2.5352187
F47: 11 | G47: =$G$2 -> 3.1 | H47: =(1+$B$28)^-F47 -> 0.71998903 | I47: =G47*H47 -> 2.231966 | L47: 11 | M47: =$G$2 -> 3.1 | N47: =(1+$B$29)^-L47 -> 0.80152875 | O47: =M47*N47 -> 2.4847391
...

Sheet Ford
A1: Bond Ticker | B1: CUSIP | C1: Company Name | D1: Settlement Date | E1: Years to Maturity | F1: FV | G1: Coupon Pmt | H1: N | I1: I/Y | J1: PV | K1: t | L1: First Coupon Date | M1: Recent Coupon Payment | N1: Coupon Months | P1: Coupon payment dates
A2: F 3 1/4” | B2: 345370DA5 | C2: Ford Motor Company | D2: 45767 | E2: =_xlfn.DAYS(H5,D2)/360 -> 6.9138889 | F2: 100 | G2: =F2*L5/2 -> 1.625 | H2: =E2*2 -> 13.827778 | I2: =N5/2 -> 0.018317223 | J2: -97.494879 | K2: =DAYS360(M2,D2,0) -> 68 | L2: 44604 | M2: 45700 | N2: Feb | O2: August | P2: 45700 | Q2: 45881
A4: Bond Ticker | B4: CUSIP | C4: Company Name | D4: Rating | E4: Amount Issued $M | F4: Amount Outstanding $M | G4: Issue Date | H4: Date of Maturity | I4: Embeded Option | J4: Call Date | K4: Call Price | L4: Coupon | M4: Coupon Freq | N4: Annual YTM | O4: Annual Yield to call
A5: F 3 1/4 02/12/2032 | B5: 345370DA5 | C5: Ford Motor Company | D5: BB+ | E5: 2500 | F5: 2500 | G5: 44512 | H5: 48256 | I5: 0.0325 | J5: 48164 | K5: 100 | L5: 0.0325 | M5: SA | N5: =B16 -> 0.036634445 | O5: =B30 -> 0.036832937
A8: Parameters | B8: Values | E8: Period | F8: Cash Flow (CF) | G8: Discount Factors (DF) | H8: Present Value (PV) | I8: Time * PV | J8: Convexity
A9: Flat Price | B9: =J2 -> -97.494879 | E9: 1 | F9: =$G$2 -> 1.625 | G9: =(1+$B$17)^-E9 -> 0.98201226 | H9: =F9*G9 -> 1.5957699 | I9: =E9*H9 -> 1.5957699 | J9: =E9*(E9+1)*H9 -> 3.1915399
A10: Days since last payment | B10: =K2 -> 68 | E10: 2 | F10: =$G$2 -> 1.625 | G10: =(1+$B$17)^-E10 -> 0.96434808 | H10: =F10*G10 -> 1.5670656 | I10: =E10*H10 -> 3.1341313 | J10: =E10*(E10+1)*H10 -> 9.4023938
A11: Total days in a coupon period | B11: =DAYS360(P2,Q2,FALSE) -> 180 | E11: 3 | F11: =$G$2 -> 1.625 | G11: =(1+$B$17)^-E11 -> 0.94700164 | H11: =F11*G11 -> 1.5388777 | I11: =E11*H11 -> 4.616633 | J11: =E11*(E11+1)*H11 -> 18.466532
A12: Annual coupon rate | B12: =L5 -> 0.0325 | E12: 4 | F12: =$G$2 -> 1.625 | G12: =(1+$B$17)^-E12 -> 0.92996723 | H12: =F12*G12 -> 1.5111967 | I12: =E12*H12 -> 6.044787 | J12: =E12*(E12+1)*H12 -> 30.223935
A13: Semi annual coupon payment | B13: =G2 -> 1.625 | E13: 5 | F13: =$G$2 -> 1.625 | G13: =(1+$B$17)^-E13 -> 0.91323922 | H13: =F13*G13 -> 1.4840137 | I13: =E13*H13 -> 7.4200687 | J13: =E13*(E13+1)*H13 -> 44.520412
A14: Accrued Interest | B14: =(B10/B11)*B13 -> 0.61388889 | E14: 6 | F14: =$G$2 -> 1.625 | G14: =(1+$B$17)^-E14 -> 0.89681211 | H14: =F14*G14 -> 1.4573197 | I14: =E14*H14 -> 8.7439181 | J14: =E14*(E14+1)*H14 -> 61.207427
A15: Full Price | B15: =B14-B9 -> 98.108768 | C15: Flat price + accrued interest | E15: 7 | F15: =$G$2 -> 1.625 | G15: =(1+$B$17)^-E15 -> 0.88068049 | H15: =F15*G15 -> 1.4311058 | I15: =E15*H15 -> 10.017741 | J15: =E15*(E15+1)*H15 -> 80.141925
A16: YTM | B16: =RATE(H2,G2,J2,F2)*2 -> 0.036634445 | E16: 8 | F16: =$G$2 -> 1.625 | G16: =(1+$B$17)^-E16 -> 0.86483904 | H16: =F16*G16 -> 1.4053634 | I16: =E16*H16 -> 11.242908 | J16: =E16*(E16+1)*H16 -> 101.18617
A17: Discount Factor (semi annual yield) | B17: =B16/2 -> 0.018317223 | E17: 9 | F17: =$G$2 -> 1.625 | G17: =(1+$B$17)^-E17 -> 0.84928255 | H17: =F17*G17 -> 1.3800841 | I17: =E17*H17 -> 12.420757 | J17: =E17*(E17+1)*H17 -> 124.20757
A18: Macaulay Duration | B18: =I23/H23 -> 12.612199 | E18: 10 | F18: =$G$2 -> 1.625 | G18: =(1+$B$17)^-E18 -> 0.83400587 | H18: =F18*G18 -> 1.3552595 | I18: =E18*H18 -> 13.552595 | J18: =E18*(E18+1)*H18 -> 149.07855
A19: Modified duration | B19: =B18/(1+B17) -> 12.385334 | E19: 11 | F19: =$G$2 -> 1.625 | G19: =(1+$B$17)^-E19 -> 0.819004 | H19: =F19*G19 -> 1.3308815 | I19: =E19*H19 -> 14.639696 | J19: =E19*(E19+1)*H19 -> 175.67636
A20: Convexity | B20: =J23/(B15*(1+B17)^2) -> 174.83517 | C20: convexity/(full price*(1+semi annual yield)^2) | E20: 12 | F20: =$G$2 -> 1.625 | G20: =(1+$B$17)^-E20 -> 0.80427197 | H20: =F20*G20 -> 1.3069419 | I20: =E20*H20 -> 15.683303 | J20: =E20*(E20+1)*H20 -> 203.88294
A21: Yield shift (bps) | B21: 100 | E21: 13 | F21: =$G$2 -> 1.625 | G21: =(1+$B$17)^-E21 -> 0.78980493 | H21: =F21*G21 -> 1.283433 | I21: =E21*H21 -> 16.684629 | J21: =E21*(E21+1)*H21 -> 233.58481
A22: Yield change in decimal | B22: =B21/10000 -> 0.01 | E22: 14 | F22: =$G$2+$F$2 -> 101.625 | G22: =(1+$B$17)^-E22 -> 0.77559813 | H22: =F22*G22 -> 78.82016 | I22: =E22*H22 -> 1103.4822 | J22: =E22*(E22+1)*H22 -> 16552.234
A23: Yield change positive (+100 bps) | B23: =B16+B22 -> 0.046634445 | E23: Total | F23: =SUM(F9:F22) -> 122.75 | G23: =SUM(G9:G22) -> 12.250868 | H23: =SUM(H9:H22) -> 97.467473 | I23: =SUM(I9:I22) -> 1229.2792 | J23: =SUM(J9:J22) -> 17787.004
A24: Yield change negative (-100 bps) | B24: =B16-B22 -> 0.026634445
A25: semi annual yield change with +100 bps | B25: =B23/2 -> 0.023317223
A26: semi annual yield change with -100 bps | B26: =B24/2 -> 0.013317223
A27: New Price with +100 bps | B27: =H45 -> 91.640645
A28: New Price with -100 bps | B28: =O45 -> 103.72335
A29: Number of periods (Yield to Call) | B29: =DAYS360(D2,J5,0)/360*2 -> 13.122222 | E29: Bond Price with +100 bps yield | L29: Bond Price with -100 bps yield
A30: YTC (Yield to call) | B30: =RATE(B29,G2,J2,K5)*2 -> 0.036832937 | E30: Period | F30: Payment SA | G30: Discount factor | H30: Present value | L30: Period | M30: Payment SA | N30: Discount factor | O30: Present value
E31: 1 | F31: =$G$2 -> 1.625 | G31: =1/(1+$B$25)^E31 -> 0.97721408 | H31: =F31*G31 -> 1.5879729 | L31: 1 | M31: =$G$2 -> 1.625 | N31: =1/(1+$B$26)^L31 -> 0.98685779 | O31: =M31*N31 -> 1.6036439
E32: 2 | F32: =$G$2 -> 1.625 | G32: =1/(1+$B$25)^E32 -> 0.95494736 | H32: =F32*G32 -> 1.5517895 | L32: 2 | M32: =$G$2 -> 1.625 | N32: =1/(1+$B$26)^L32 -> 0.97388831 | O32: =M32*N32 -> 1.5825685
E33: 3 | F33: =$G$2 -> 1.625 | G33: =1/(1+$B$25)^E33 -> 0.93318801 | H33: =F33*G33 -> 1.5164305 | L33: 3 | M33: =$G$2 -> 1.625 | N33: =1/(1+$B$26)^L33 -> 0.96108927 | O33: =M33*N33 -> 1.5617701
E34: 4 | F34: =$G$2 -> 1.625 | G34: =1/(1+$B$25)^E34 -> 0.91192446 | H34: =F34*G34 -> 1.4818773 | L34: 4 | M34: =$G$2 -> 1.625 | N34: =1/(1+$B$26)^L34 -> 0.94845844 | O34: =M34*N34 -> 1.541245
E35: 5 | F35: =$G$2 -> 1.625 | G35: =1/(1+$B$25)^E35 -> 0.89114543 | H35: =F35*G35 -> 1.4481113 | L35: 5 | M35: =$G$2 -> 1.625 | N35: =1/(1+$B$26)^L35 -> 0.9359936 | O35: =M35*N35 -> 1.5209896
E36: 6 | F36: =$G$2 -> 1.625 | G36: =1/(1+$B$25)^E36 -> 0.87083986 | H36: =F36*G36 -> 1.4151148 | L36: 6 | M36: =$G$2 -> 1.625 | N36: =1/(1+$B$26)^L36 -> 0.92369258 | O36: =M36*N36 -> 1.5010004
E37: 7 | F37: =$G$2 -> 1.625 | G37: =1/(1+$B$25)^E37 -> 0.85099697 | H37: =F37*G37 -> 1.3828701 | L37: 7 | M37: =$G$2 -> 1.625 | N37: =1/(1+$B$26)^L37 -> 0.91155322 | O37: =M37*N37 -> 1.481274
E38: 8 | F38: =$G$2 -> 1.625 | G38: =1/(1+$B$25)^E38 -> 0.83160623 | H38: =F38*G38 -> 1.3513601 | L38: 8 | M38: =$G$2 -> 1.625 | N38: =1/(1+$B$26)^L38 -> 0.8995734 | O38: =M38*N38 -> 1.4618068
E39: 9 | F39: =$G$2 -> 1.625 | G39: =1/(1+$B$25)^E39 -> 0.81265731 | H39: =F39*G39 -> 1.3205681 | L39: 9 | M39: =$G$2 -> 1.625 | N39: =1/(1+$B$26)^L39 -> 0.88775103 | O39: =M39*N39 -> 1.4425954
E40: 10 | F40: =$G$2 -> 1.625 | G40: =1/(1+$B$25)^E40 -> 0.79414017 | H40: =F40*G40 -> 1.2904778 | L40: 10 | M40: =$G$2 -> 1.625 | N40: =1/(1+$B$26)^L40 -> 0.87608402 | O40: =M40*N40 -> 1.4236365
E41: 11 | F41: =$G$2 -> 1.625 | G41: =1/(1+$B$25)^E41 -> 0.77604496 | H41: =F41*G41 -> 1.2610731 | L41: 11 | M41: =$G$2 -> 1.625 | N41: =1/(1+$B$26)^L41 -> 0.86457034 | O41: =M41*N41 -> 1.4049268
E42: 12 | F42: =$G$2 -> 1.625 | G42: =1/(1+$B$25)^E42 -> 0.75836206 | H42: =F42*G42 -> 1.2323383 | L42: 12 | M42: =$G$2 -> 1.625 | N42: =1/(1+$B$26)^L42 -> 0.85320798 | O42: =M42*N42 -> 1.386463
E43: 13 | F43: =$G$2 -> 1.625 | G43: =1/(1+$B$25)^E43 -> 0.74108208 | H43: =F43*G43 -> 1.2042584 | L43: 13 | M43: =$G$2 -> 1.625 | N43: =1/(1+$B$26)^L43 -> 0.84199495 | O43: =M43*N43 -> 1.3682418
...

Sheet Portfolio Allocation
A3: Total Portfolio value | B3: 1000000
A5: Bond name | B5: Allocation in % | C5: Number of Bonds allocated to portfolio | D5: Par value | E5: Coupon rate | F5: YTM | G5: Duration | H5: Convexity | I5: Coupon payment | J5: YTM contribution | K5: Duration contribution | L5: Convexity Contribution | M5: Present Value | N5: Current Portfolio Price
A6: Amazon | B6: 0.33 | C6: =Table7[[#This Row],[Par value]]*Table7[[#This Row],[Allocation in %]] -> 330 | D6: 1000 | E6: =Amazon!L5 -> 0.036 | F6: =Amazon!N5 -> 0.046337606 | G6: =Amazon!E2 -> 6.9863014 | H6: =Amazon!B20 -> 170.98198 | I6: =Table7[[#This Row],[Coupon rate]]*Table7[[#This Row],[Number of Bonds allocated to portfolio]]*Table7[[#This Row],[Par value]] -> 11880 | J6: =Table7[[#This Row],[YTM]]*Table7[[#This Row],[Par value]]*Table7[[#This Row],[Number of Bonds allocated to portfolio]] -> 15291.41 | K6: =Table7[[#This Row],[Duration]]*Table7[[#This Row],[Par value]]*Table7[[#This Row],[Number of Bonds allocated to portfolio]] -> 2305479.5 | L6: =Table7[[#This Row],[Number of Bonds allocated to portfolio]]*Table7[[#This Row],[Par value]]*Table7[[#This Row],[Convexity]] -> 56424053 | M6: =(Amazon!J2)*-1 -> 93.89 | N6: =Table7[[#This Row],[Present Value]]*Table7[[#This Row],[Number of Bonds allocated to portfolio]] -> 30983.7
A7: Disney | B7: 0.27 | C7: =Table7[[#This Row],[Par value]]*Table7[[#This Row],[Allocation in %]] -> 270 | D7: 1000 | E7: =Disney!I8 -> 0.062 | F7: =Disney!K8 -> 0.050631671 | G7: =Disney!E2 -> 9.5 | H7: =Disney!B23 -> 252.69843 | I7: =Table7[[#This Row],[Coupon rate]]*Table7[[#This Row],[Number of Bonds allocated to portfolio]]*Table7[[#This Row],[Par value]] -> 16740 | J7: =Table7[[#This Row],[YTM]]*Table7[[#This Row],[Par value]]*Table7[[#This Row],[Number of Bonds allocated to portfolio]] -> 13670.551 | K7: =Table7[[#This Row],[Duration]]*Table7[[#This Row],[Par value]]*Table7[[#This Row],[Number of Bonds allocated to portfolio]] -> 2565000 | L7: =Table7[[#This Row],[Number of Bonds allocated to portfolio]]*Table7[[#This Row],[Par value]]*Table7[[#This Row],[Convexity]] -> 68228575 | M7: =Disney!J2 -> 108.49 | N7: =Table7[[#This Row],[Present Value]]*Table7[[#This Row],[Number of Bonds allocated to portfolio]] -> 29292.3
A8: Microsoft | B8: 0.22 | C8: =Table7[[#This Row],[Par value]]*Table7[[#This Row],[Allocation in %]] -> 220 | D8: 1000 | E8: =Microsoft!L5 -> 0.035 | F8: =Microsoft!N5 -> 0.045234641 | G8: =Microsoft!E2 -> 10 | H8: =Microsoft!B20 -> 317.38072 | I8: =Table7[[#This Row],[Coupon rate]]*Table7[[#This Row],[Number of Bonds allocated to portfolio]]*Table7[[#This Row],[Par value]] -> 7700 | J8: =Table7[[#This Row],[YTM]]*Table7[[#This Row],[Par value]]*Table7[[#This Row],[Number of Bonds allocated to portfolio]] -> 9951.621 | K8: =Table7[[#This Row],[Duration]]*Table7[[#This Row],[Par value]]*Table7[[#This Row],[Number of Bonds allocated to portfolio]] -> 2200000 | L8: =Table7[[#This Row],[Number of Bonds allocated to portfolio]]*Table7[[#This Row],[Par value]]*Table7[[#This Row],[Convexity]] -> 69823758 | M8: =(Microsoft!J2)*-1 -> 91.84 | N8: =Table7[[#This Row],[Present Value]]*Table7[[#This Row],[Number of Bonds allocated to portfolio]] -> 20204.8
A9: Ford | B9: 0.18 | C9: =Table7[[#This Row],[Par value]]*Table7[[#This Row],[Allocation in %]] -> 180 | D9: 1000 | E9: =Ford!L5 -> 0.0325 | F9: =Ford!N5 -> 0.036634445 | G9: =Ford!E2 -> 6.9138889 | H9: =Ford!B20 -> 174.83517 | I9: =Table7[[#This Row],[Coupon rate]]*Table7[[#This Row],[Number of Bonds allocated to portfolio]]*Table7[[#This Row],[Par value]] -> 5850 | J9: =Table7[[#This Row],[YTM]]*Table7[[#This Row],[Par value]]*Table7[[#This Row],[Number of Bonds allocated to portfolio]] -> 6594.2002 | K9: =Table7[[#This Row],[Duration]]*Table7[[#This Row],[Par value]]*Table7[[#This Row],[Number of Bonds allocated to portfolio]] -> 1244500 | L9: =Table7[[#This Row],[Number of Bonds allocated to portfolio]]*Table7[[#This Row],[Par value]]*Table7[[#This Row],[Convexity]] -> 31470331 | M9: =(Ford!J2)*-1 -> 97.494879 | N9: =Table7[[#This Row],[Present Value]]*Table7[[#This Row],[Number of Bonds allocated to portfolio]] -> 17549.078
A10: Total | B10: =SUM(B6:B9) -> 1 | C10: =SUM(C6:C9) -> 1000 | D10: =SUM(D6:D9) -> 4000 | E10: =SUM(E6:E9) -> 0.1655 | F10: =SUM(F6:F9) -> 0.17883836 | G10: =SUM(G6:G9) -> 33.40019 | H10: =SUM(H6:H9) -> 915.8963 | I10: =SUM(I6:I9) -> 42170 | ... N10: =SUM(N6:N9) -> 98029.878
A14: Portfolio Parameters | B14: Value | C14: Desrciption
A15: Average coupon of Portfolio | B15: =I10/B3 -> 0.04217 | C15: Total coupon on portfolio/Total Portfolio Value
A16: YTM of portfolio | B16: =J10/B3 -> 0.045507782 | C16: Total YTM/Total Portfolio Value
A17: Duration of Portfolio in Years | B17: =K10/B3 -> 8.3149795 | C17: Total duration/Portfolio Value
A18: Convexity of Portfolio | B18: =L10/B3 -> 225.94672 | C18: Total convexity/ Portfolio Value
A19: sensitivity of the portfolio with +100 bps shift in yield | B19: =B22+B21 -> -0.071852459 | C19: Duration effect + Convexity effect (+100 bps)
A20: sensitivity of the portfolio with -100 bps shift in yield | B20: =B23+B24 -> 0.09444713 | C20: Duration effect + Convexity effect (-100 bps)
A21: Duration effect +100 bps | B21: =-B17*B25 -> -0.083149795 | C21: change in the portfolio value due to duration impact (+100 bps)
A22: Convexity effect +100 bps | B22: =($B$18*(B25)^2)/2 -> 0.011297336 | C22: change in the portfolio value due to convextiy impact (+100 bps)
A23: Duration effect -100 bps | B23: =-B17*-B25 -> 0.083149795 | C23: change in the portfolio value due to duration impact (-100 bps)
A24: Convexity effect -100 bps | B24: =($B$18*(-B25)^2)/2 -> 0.011297336 | C24: change in the portfolio value due to convextiy impact (-100 bps)
A25: Yield shift | B25: 0.01 | C25: Incremental change in yield, expressed as fraction
A26: Annual yield shift +100bps | B26: =B16+B25 -> 0.055507782 | C26: Annual updated yield with +100 bps increase
A27: Annual yield shift -100bps | B27: =B16-B25 -> 0.035507782 | C27: Annual updated yield with -100 bps decrease
A28: Portfolio Value | B28: =SUMPRODUCT(M6:M9,C6:C9) -> 98029.878 | C28: Total portfolio value based on the present value and number of bond allocated to portfolio
A29: New Price of Portfolio +100 bps | B29: =$B$28*(1+B19) -> 90986.19 | C29: Portfolio value with recalculated with +100 bps shift
A30: New Price of Portfolio - 100 bps | B30: =$B$28*(1+B20) -> 107288.52 | C30: Portfolio value with recalculated with -100 bps shift

Sheet Summary
A1: Portfolio Summary
A2: Portfolio value | B2: ='Portfolio Allocation'!B3 -> 1000000
A3: Average coupon rate | B3: ='Portfolio Allocation'!B15 -> 0.04217
A4: YTM of the Portfolio | B4: ='Portfolio Allocation'!B16 -> 0.045507782
A5: Duration (in years) | B5: ='Portfolio Allocation'!B17 -> 8.3149795
A6: Convexity | B6: ='Portfolio Allocation'!B18 -> 225.94672
A7: sensitivity with +100 bps shift | B7: ='Portfolio Allocation'!B19 -> -0.071852459
A8: sensitivity with -100 bps shift | B8: ='Portfolio Allocation'!B20 -> 0.09444713
A10: Corporate sectors
A11: Amazon | B11: E-commerce
A12: Disney | B12: Entertainment
A13: Microsoft | B13: Technology
A14: Ford | B14: Automotive
A16: Reason to select these bonds
A17: Amazon | B17: Strong revenue growth,consistent expanision, resilience to economic downturns and high investment grade bond due to financial stability
A18: Disney | B18: Reliable income backed by company's vast intellectual property and global reach, operation spans in multiple areas reducing sector specific risks. Entertainment based revenue excels in economic growth
A19: Microsoft | B19: Ability to withstand economic cycles due to innovation, stable revenues driven by its software, hardware and cloud services. Strong liquidity and extensive portfolio
A20: Ford | B20: Historical market presence and reputation give its bonds stability, Investment in EV position for long term growth. Global operation reduces reliance on a single market.
A22: Portfolio Performance
